<?xml version="1.0" encoding="UTF-8"?><testsuite name="nosetests" tests="5" errors="0" failures="1" skip="0"><testcase classname="tests.ExperimentTest.MyTestCase" name="test_t1" time="0.000"></testcase><testcase classname="tests.ExperimentTest.MyTestCase" name="test_t2" time="0.000"></testcase><testcase classname="tests.ExperimentTest.MyTestCase" name="test_t3" time="0.000"></testcase><testcase classname="tests.ExperimentTest.MyTestCase" name="test_t4" time="0.000"></testcase><testcase classname="tests.ExperimentTest.MyTestCase" name="test_t5" time="0.000"><failure type="exceptions.AssertionError" message="0 != -1"><![CDATA[Traceback (most recent call last):
  File "/usr/lib/python2.7/unittest/case.py", line 331, in run
    testMethod()
  File "/home/yikong/workspace/apt_lab3/tests/ExperimentTest.py", line 24, in test_t5
    self.assertEqual(r1, -1)
  File "/usr/lib/python2.7/unittest/case.py", line 515, in assertEqual
    assertion_func(first, second, msg=msg)
  File "/usr/lib/python2.7/unittest/case.py", line 508, in _baseAssertEqual
    raise self.failureException(msg)
AssertionError: 0 != -1
]]></failure></testcase></testsuite>